<robot name="FRANCIS">
	<link name="body">
		<visual>
			<origin xyz="0 0 1" rpy="0 0 0"/>
			<geometry>
				<cylinder radius="0.375" length="0.05"/>
			</geometry>
	   </visual>
	   	<collision>
			<origin xyz="0 0 1" rpy="0 0 0"/>
			<geometry>
				<cylinder radius="0.375" length="0.05"/>
			</geometry>
	   </collision>
	</link>
    <link name="leg1_top_shoulder1">
		<visual>
			<origin xyz="0 0 0" rpy="0 0 0"/>
			<geometry>
				<sphere radius="0.07"/>
			</geometry>
		</visual>
		<collision>
			<origin xyz="0 0 0" rpy="0 0 0"/>
			<geometry>
				<sphere radius="0.07"/>
			</geometry>
		</collision>
	</link>
    <link name="leg1_top_shoulder2">
		<visual>
			<origin xyz="0 0 0" rpy="0 0 0"/>
			<geometry>
				<sphere radius="0.07"/>
			</geometry>
		</visual>
		<collision>
			<origin xyz="0 0 0" rpy="0 0 0"/>
			<geometry>
				<sphere radius="0.07"/>
			</geometry>
		</collision>
	</link>
    <link name="leg1_top_shoulder3">
		<visual>
			<origin xyz="0 0 0" rpy="0 0 0"/>
			<geometry>
				<sphere radius="0.07"/>
			</geometry>
		</visual>
		<collision>
			<origin xyz="0 0 0" rpy="0 0 0"/>
			<geometry>
				<sphere radius="0.07"/>
			</geometry>
		</collision>
	</link>
	<link name="leg1_top_leg">
		<visual>
			<origin xyz="0 0 0" rpy="0 0 0"/>
			<geometry>
				<box size="0.08 0.08 0.559"/>
			</geometry>
		</visual>
		<collision>
			<origin xyz="0 0 0" rpy="0 0 0"/>
			<geometry>
				<box size="0.08 0.08 0.559"/>
			</geometry>
		</collision>
	</link>
    <link name="leg1_mid_shoulder">
		<visual>
			<origin xyz="0 0 0" rpy="0 0 0"/>
			<geometry>
				<sphere radius="0.07"/>
			</geometry>
		</visual>
		<collision>
			<origin xyz="0 0 0" rpy="0 0 0"/>
			<geometry>
				<sphere radius="0.07"/>
			</geometry>
		</collision>
	</link>
	<link name="leg1_mid_leg">
		<visual>
			<origin xyz="0 0 0" rpy="0 0 0"/>
			<geometry>
				<box size="0.08 0.08 0.800"/>
			</geometry>
		</visual>
		<collision>
			<origin xyz="0 0 0" rpy="0 0 0"/>
			<geometry>
				<box size="0.08 0.08 0.800"/>
			</geometry>
		</collision>
	</link>
    <link name="leg1_bot_shoulder">
		<visual>
			<origin xyz="0 0 0" rpy="0 0 0"/>
			<geometry>
				<sphere radius="0.07"/>
			</geometry>
		</visual>
		<collision>
			<origin xyz="0 0 0" rpy="0 0 0"/>
			<geometry>
				<sphere radius="0.07"/>
			</geometry>
		</collision>
	</link>
	<link name="leg1_bot_leg">
		<visual>
			<origin xyz="0 0 0" rpy="0 0 0"/>
			<geometry>
				<box size="0.08 0.08 1.03"/>
			</geometry>
		</visual>
		<collision>
			<origin xyz="0 0 0" rpy="0 0 0"/>
			<geometry>
				<box size="0.08 0.08 1.03"/>
			</geometry>
		</collision>
	</link>
	<joint name="leg1_top_articulation1" type="revolute">
    	<parent link="body"/>
		<child link="leg1_top_shoulder1"/>
		<origin xyz="0.375 0 1" rpy="0 0 0"/>
		<axis xyz="0 0 1"/>
		<limit effort="30" velocity="1.0" lower="-2" upper="2" />
	</joint>
	<joint name="leg1_top_articulation2" type="revolute">
    	<parent link="leg1_top_shoulder1"/>
		<child link="leg1_top_shoulder2"/>
		<origin xyz="0 0 0" rpy="0 0 0"/>
		<axis xyz="1 0 0"/>
		<limit effort="30" velocity="1.0" lower="-1.56" upper="1.56" />
	</joint>
	<joint name="leg1_top_articulation3" type="revolute"> <!-- -0.65 -->
    	<parent link="leg1_top_shoulder2"/>
		<child link="leg1_top_shoulder3"/>
		<origin xyz="0 0 0" rpy="0 0 0"/>
		<axis xyz="0 1 0"/>
		<limit effort="30" velocity="1.0" lower="-2.5" upper="1" />
	</joint>
	<joint name="leg1_top_static" type="fixed">
		<parent link="leg1_top_shoulder3"/>
		<child link="leg1_top_leg"/>
		<origin xyz="0.1 0 -0.25" rpy="0 -0.352 0"/>
	</joint>
	<joint name="leg1_mid_articulation" type="revolute"> <!-- -0.14 -->
    	<parent link="leg1_top_leg"/>
		<child link="leg1_mid_shoulder"/>
		<origin xyz="0 0 -0.25" rpy="0 0 0"/>
		<axis xyz="0 1 0"/>
		<limit effort="30" velocity="1.0" lower="-0.95" upper="2" />
	</joint>
	<joint name="leg1_mid_static" type="fixed">
		<parent link="leg1_mid_shoulder"/>
		<child link="leg1_mid_leg"/>
		<origin xyz="0.333 0 0.15" rpy="0 -2 0"/>
	</joint>
	<joint name="leg1_bot_articulation" type="revolute"> <!-- 2.5 -->
    	<parent link="leg1_mid_leg"/>
		<child link="leg1_bot_shoulder"/>
		<origin xyz="0 0 -0.4" rpy="0 0 0"/>
		<axis xyz="0 1 0"/>
		<limit effort="30" velocity="1.0" lower="-1.9" upper="1.12" />
	</joint>
	<joint name="leg1_bot_static" type="fixed">
		<parent link="leg1_bot_shoulder"/>
		<child link="leg1_bot_leg"/>
		<origin xyz="-0.5 0 0.165" rpy="0 1.9 0"/>
	</joint>
</robot>